Workbook

Sheet Dashboard
A3: Row Labels | B3: Sum of Outstanding_Amount | E3: Row Labels | F3: Sum of Outstanding_Amount
A4: Delhi_North | B4: 0.28442937 | E4: Others | F4: 0.22550209
A5: Mumbai_Central | B5: 0.27591952 | E5: Services | F5: 0.23745582
A6: Kolkata_East | B6: 0.25970733 | E6: Trading | F6: 0.2635894
A7: Bangalore_South | B7: 0.17994377 | E7: Manufacturing | F7: 0.27345269
A8: Grand Total | B8: 1 | E8: Grand Total | F8: 1
A13: Row Labels | B13: Sum of Outstanding_Amount | E13: Sum of Outstanding_Amount | F13: Column Labels
A14: High | B14: 0.06635974 | E14: Row Labels | F14: Bangalore_South | G14: Delhi_North | H14: Kolkata_East | I14: Mumbai_Central | J14: Grand Total
A15: Low | B15: 0.85293637 | E15: NPA | F15: 0 | G15: 0 | H15: 0.022728257 | I15: 0.0075510393 | J15: 0.030279296
A16: Medium | B16: 0.08070389 | E16: SMA-0 | F16: 0.16278437 | G16: 0.25782201 | H16: 0.19228589 | I16: 0.2400441 | J16: 0.85293637
A17: Grand Total | B17: 1 | E17: SMA-1 | F17: 0.017159394 | G17: 0.022935153 | H17: 0.028253338 | I17: 0.012356004 | J17: 0.08070389
E18: SMA-2 | F18: 0 | G18: 0.0036722147 | H18: 0.016439852 | I18: 0.015968377 | J18: 0.036080444
E19: Grand Total | F19: 0.17994377 | G19: 0.28442937 | H19: 0.25970733 | I19: 0.27591952 | J19: 1

Sheet SME_Portfolio
A1: Loan_ID | B1: Customer_ID | C1: Branch | D1: Region | E1: Relationship_Manager | F1: Product_Type | G1: Sanction_Amount | H1: Outstanding_Amount | I1: Undrawn_Limit | J1: Limit_Utilization_% | K1: Interest_Rate | L1: Days_Past_Due | M1: SMA_Category | N1: NPA_Flag | O1: Risk_Category | P1: Restructured_Flag | Q1: Bounce_Count_Last_6M | R1: Sector | S1: Industry_Subtype | T1: Years_in_Business | U1: Annual_Turnover | V1: Internal_Credit_Rating | W1: Sanction_Date | X1: Disbursement_Date | Y1: NPA_Amount | Z1: Reporting_Month
A2: LN00001 | B2: CUST0041 | C2: Mumbai_Central | D2: North | E2: RM_1 | F2: OD | G2: 11030239 | H2: 8242631 | I2: 2787608 | J2: 0.75 | K2: 11.82 | L2: 14 | M2: SMA-0 | N2: 0 | O2: Low | P2: 1 | Q2: 5 | R2: Trading | S2: Textile | T2: 2 | U2: 281379958 | V2: C | W2: 44985 | X2: 44991 | Y2: =IF(Table1[[#This Row],[NPA_Flag]]=1, Table1[[#This Row],[Outstanding_Amount]], 0) -> 0 | Z2: 46053
A3: LN00002 | B3: CUST0166 | C3: Kolkata_East | D3: South | E3: RM_6 | F3: OD | G3: 5326528 | H3: 4285675 | I3: 1040853 | J3: 0.8 | K3: 13.9 | L3: 30 | M3: SMA-0 | N3: 0 | O3: Low | P3: 1 | Q3: 4 | R3: Manufacturing | S3: Textile | T3: 2 | U3: 141604517 | V3: C | W3: 43885 | X3: 43892 | Y3: =IF(Table1[[#This Row],[NPA_Flag]]=1, Table1[[#This Row],[Outstanding_Amount]], 0) -> 0 | Z3: 46053
A4: LN00003 | B4: CUST0067 | C4: Bangalore_South | D4: North | E4: RM_8 | F4: CC | G4: 8849837 | H4: 7862541 | I4: 987296 | J4: 0.89 | K4: 10.91 | L4: 25 | M4: SMA-0 | N4: 0 | O4: Low | P4: 1 | Q4: 2 | R4: Services | S4: FMCG | T4: 16 | U4: 137169334 | V4: A | W4: 44804 | X4: 44814 | Y4: =IF(Table1[[#This Row],[NPA_Flag]]=1, Table1[[#This Row],[Outstanding_Amount]], 0) -> 0 | Z4: 46053
A5: LN00004 | B5: CUST0039 | C5: Bangalore_South | D5: East | E5: RM_2 | F5: Term Loan | G5: 8582608 | H5: 5628480 | I5: 2954128 | J5: 0.66 | K5: 12.18 | L5: 56 | M5: SMA-1 | N5: 0 | O5: Medium | P5: 1 | Q5: 1 | R5: Services | S5: Pharma | T5: 11 | U5: 399482094 | V5: D | W5: 44679 | X5: 44685 | Y5: =IF(Table1[[#This Row],[NPA_Flag]]=1, Table1[[#This Row],[Outstanding_Amount]], 0) -> 0 | Z5: 46053
A6: LN00005 | B6: CUST0081 | C6: Bangalore_South | D6: West | E6: RM_1 | F6: CC | G6: 8883596 | H6: 5906571 | I6: 2977025 | J6: 0.66 | K6: 12.34 | L6: 2 | M6: SMA-0 | N6: 0 | O6: Low | P6: 0 | Q6: 4 | R6: Services | S6: Pharma | T6: 18 | U6: 93885263 | V6: D | W6: 43954 | X6: 43957 | Y6: =IF(Table1[[#This Row],[NPA_Flag]]=1, Table1[[#This Row],[Outstanding_Amount]], 0) -> 0 | Z6: 46053
A7: LN00006 | B7: CUST0080 | C7: Bangalore_South | D7: South | E7: RM_2 | F7: Term Loan | G7: 5556574 | H7: 4604634 | I7: 951940 | J7: 0.83 | K7: 11.81 | L7: 26 | M7: SMA-0 | N7: 0 | O7: Low | P7: 1 | Q7: 5 | R7: Manufacturing | S7: Electronics | T7: 16 | U7: 367048133 | V7: B | W7: 45308 | X7: 45316 | Y7: =IF(Table1[[#This Row],[NPA_Flag]]=1, Table1[[#This Row],[Outstanding_Amount]], 0) -> 0 | Z7: 46053
A8: LN00007 | B8: CUST0110 | C8: Kolkata_East | D8: North | E8: RM_8 | F8: LAP | G8: 4412427 | H8: 2707114 | I8: 1705313 | J8: 0.61 | K8: 9.02 | L8: 146 | M8: NPA | N8: 1 | O8: High | P8: 0 | Q8: 2 | R8: Services | S8: Pharma | T8: 22 | U8: 135100691 | V8: C | W8: 45033 | X8: 45040 | Y8: =IF(Table1[[#This Row],[NPA_Flag]]=1, Table1[[#This Row],[Outstanding_Amount]], 0) -> 2707114 | Z8: 46053
A9: LN00008 | B9: CUST0030 | C9: Mumbai_Central | D9: West | E9: RM_5 | F9: Term Loan | G9: 5466203 | H9: 4661863 | I9: 804340 | J9: 0.85 | K9: 10.24 | L9: 13 | M9: SMA-0 | N9: 0 | O9: Low | P9: 0 | Q9: 1 | R9: Services | S9: Textile | T9: 17 | U9: 412525472 | V9: C | W9: 44082 | X9: 44088 | Y9: =IF(Table1[[#This Row],[NPA_Flag]]=1, Table1[[#This Row],[Outstanding_Amount]], 0) -> 0 | Z9: 46053
A10: LN00009 | B10: CUST0133 | C10: Mumbai_Central | D10: South | E10: RM_2 | F10: OD | G10: 11387387 | H10: 9375901 | I10: 2011486 | J10: 0.82 | K10: 12.5 | L10: 18 | M10: SMA-0 | N10: 0 | O10: Low | P10: 1 | Q10: 5 | R10: Trading | S10: Textile | T10: 7 | U10: 246872703 | V10: C | W10: 45214 | X10: 45218 | Y10: =IF(Table1[[#This Row],[NPA_Flag]]=1, Table1[[#This Row],[Outstanding_Amount]], 0) -> 0 | Z10: 46053
A11: LN00010 | B11: CUST0184 | C11: Delhi_North | D11: East | E11: RM_5 | F11: OD | G11: 7919175 | H11: 6740846 | I11: 1178329 | J11: 0.85 | K11: 10.28 | L11: 19 | M11: SMA-0 | N11: 0 | O11: Low | P11: 1 | Q11: 2 | R11: Manufacturing | S11: Auto Parts | T11: 10 | U11: 171359832 | V11: C | W11: 44767 | X11: 44777 | Y11: =IF(Table1[[#This Row],[NPA_Flag]]=1, Table1[[#This Row],[Outstanding_Amount]], 0) -> 0 | Z11: 46053
A12: LN00011 | B12: CUST0090 | C12: Kolkata_East | D12: North | E12: RM_3 | F12: LAP | G12: 3464650 | H12: 2877445 | I12: 587205 | J12: 0.83 | K12: 13.72 | L12: 15 | M12: SMA-0 | N12: 0 | O12: Low | P12: 0 | Q12: 4 | R12: Trading | S12: Auto Parts | T12: 19 | U12: 68569259 | V12: B | W12: 45296 | X12: 45301 | Y12: =IF(Table1[[#This Row],[NPA_Flag]]=1, Table1[[#This Row],[Outstanding_Amount]], 0) -> 0 | Z12: 46053
A13: LN00012 | B13: CUST0022 | C13: Delhi_North | D13: North | E13: RM_7 | F13: LAP | G13: 6978497 | H13: 5473652 | I13: 1504845 | J13: 0.78 | K13: 12.73 | L13: 8 | M13: SMA-0 | N13: 0 | O13: Low | P13: 0 | Q13: 0 | R13: Trading | S13: FMCG | T13: 1 | U13: 366690008 | V13: C | W13: 44702 | X13: 44709 | Y13: =IF(Table1[[#This Row],[NPA_Flag]]=1, Table1[[#This Row],[Outstanding_Amount]], 0) -> 0 | Z13: 46053
... A301: LN00300 | B301: CUST0020 | C301: Kolkata_East | D301: South | E301: RM_3 | F301: OD | G301: 3226284 | H301: 2554410 | I301: 671874 | J301: 0.79 | K301: 12.1 | L301: 27 | M301: SMA-0 | N301: 0 | O301: Low | P301: 1 | Q301: 5 | R301: Others | S301: Pharma | T301: 6 | U301: 439706351 | V301: D | W301: 44115 | X301: 44116 | Y301: =IF(Table1[[#This Row],[NPA_Flag]]=1, Table1[[#This Row],[Outstanding_Amount]], 0) -> 0 | Z301: 46053

Sheet KPI
A1: Total Portfolio Exposure | B1: =SUM(Table1[Outstanding_Amount]) -> 2062659900
A2: Gross NPA % | B2: =SUMIFS(Table1[Outstanding_Amount],Table1[NPA_Flag],1)/SUM(Table1[Outstanding_Amount]) -> 0.030279296
A3: High Risk Exposure % | B3: =SUMIFS(Table1[Outstanding_Amount],Table1[Risk_Category],"High")/SUM(Table1[Outstanding_Amount]) -> 0.06635974
A4: Sector Concentration Manufacturing | B4: =SUMIFS(Table1[Outstanding_Amount],Table1[Sector],"Manufacturing")/SUM(Table1[Outstanding_Amount])*100 -> 27.345269
A5: Average Utilisation % | B5: =AVERAGE(Table1[Limit_Utilization_%])*100 -> 78.29
A6: Total Accounts | B6: =COUNTA(Table1[Customer_ID]) -> 300
A7: Highest Exposure Branch | B7: =INDEX(E8:E11, MATCH(MAX(F8:F11), F8:F11,0)) -> Delhi_North | E7: Branch | F7: Exposure | G7: NPA%
A8: Highest NPA Branch | B8: =INDEX(E8:E11,MATCH(MAX(G8:G11),G8:G11,0)) -> Kolkata_East | E8: Delhi_North | F8: =SUMIFS(Table1[Outstanding_Amount],Table1[Branch],E8) -> 586681066 | G8: =SUMIFS(Table1[Outstanding_Amount],Table1[Branch],E8,Table1[NPA_Flag],1)/SUMIFS(Table1[Outstanding_Amount],Table1[Branch],E8)*100 -> 0
E9: Mumbai_Central | F9: =SUMIFS(Table1[Outstanding_Amount],Table1[Branch],E9) -> 569128135 | G9: =SUMIFS(Table1[Outstanding_Amount],Table1[Branch],E9,Table1[NPA_Flag],1)/SUMIFS(Table1[Outstanding_Amount],Table1[Branch],E9)*100 -> 2.7366818
E10: Kolkata_East | F10: =SUMIFS(Table1[Outstanding_Amount],Table1[Branch],E10) -> 535687904 | G10: =SUMIFS(Table1[Outstanding_Amount],Table1[Branch],E10,Table1[NPA_Flag],1)/SUMIFS(Table1[Outstanding_Amount],Table1[Branch],E10)*100 -> 8.7514883
E11: Bangalore_South | F11: =SUMIFS(Table1[Outstanding_Amount],Table1[Branch],E11) -> 371162795 | G11: =SUMIFS(Table1[Outstanding_Amount],Table1[Branch],E11,Table1[NPA_Flag],1)/SUMIFS(Table1[Outstanding_Amount],Table1[Branch],E11)*100 -> 0

Sheet Sheet2
A1: Loan_ID | B1: Customer_ID | C1: Branch | D1: Region | E1: Relationship_Manager | F1: Product_Type | G1: Sanction_Amount | H1: Outstanding_Amount | I1: Undrawn_Limit | J1: Limit_Utilization_% | K1: Interest_Rate | L1: Days_Past_Due | M1: SMA_Category | N1: NPA_Flag | O1: Risk_Category | P1: Restructured_Flag | Q1: Bounce_Count_Last_6M | R1: Sector | S1: Industry_Subtype | T1: Years_in_Business | U1: Annual_Turnover | V1: Internal_Credit_Rating | W1: Sanction_Date | X1: Disbursement_Date | Y1: Reporting_Month
A2: LN00300 | B2: CUST0020 | C2: Kolkata_East | D2: South | E2: RM_3 | F2: OD | G2: 3226284 | H2: 2554410 | I2: 671874 | J2: 0.79 | K2: 12.1 | L2: 27 | M2: SMA-0 | N2: 0 | O2: Low | P2: 1 | Q2: 5 | R2: Others | S2: Pharma | T2: 6 | U2: 439706351 | V2: D | W2: 44115 | X2: 44116 | Y2: 46053
A3: LN00298 | B3: CUST0086 | C3: Mumbai_Central | D3: South | E3: RM_5 | F3: LAP | G3: 4701919 | H3: 3675554 | I3: 1026365 | J3: 0.78 | K3: 10.06 | L3: 48 | M3: SMA-1 | N3: 0 | O3: Medium | P3: 0 | Q3: 4 | R3: Others | S3: Textile | T3: 23 | U3: 102905017 | V3: D | W3: 45113 | X3: 45119 | Y3: 46053
A4: LN00296 | B4: CUST0103 | C4: Bangalore_South | D4: South | E4: RM_2 | F4: OD | G4: 4653119 | H4: 3045684 | I4: 1607435 | J4: 0.65 | K4: 9.93 | L4: 27 | M4: SMA-0 | N4: 0 | O4: Low | P4: 1 | Q4: 2 | R4: Others | S4: FMCG | T4: 20 | U4: 488492703 | V4: D | W4: 43906 | X4: 43914 | Y4: 46053
A5: LN00289 | B5: CUST0041 | C5: Delhi_North | D5: West | E5: RM_1 | F5: Term Loan | G5: 11148267 | H5: 8698898 | I5: 2449369 | J5: 0.78 | K5: 12.17 | L5: 14 | M5: SMA-0 | N5: 0 | O5: Low | P5: 0 | Q5: 5 | R5: Others | S5: Textile | T5: 22 | U5: 432304436 | V5: B | W5: 45120 | X5: 45122 | Y5: 46053
A6: LN00286 | B6: CUST0078 | C6: Delhi_North | D6: West | E6: RM_2 | F6: OD | G6: 8681635 | H6: 8193512 | I6: 488123 | J6: 0.94 | K6: 11.6 | L6: 25 | M6: SMA-0 | N6: 0 | O6: Low | P6: 0 | Q6: 1 | R6: Others | S6: Pharma | T6: 25 | U6: 111991591 | V6: D | W6: 44736 | X6: 44737 | Y6: 46053
A7: LN00281 | B7: CUST0144 | C7: Delhi_North | D7: South | E7: RM_4 | F7: Term Loan | G7: 6174186 | H7: 5801894 | I7: 372292 | J7: 0.94 | K7: 11.77 | L7: 11 | M7: SMA-0 | N7: 0 | O7: Low | P7: 1 | Q7: 2 | R7: Others | S7: Textile | T7: 12 | U7: 179791588 | V7: A | W7: 44153 | X7: 44156 | Y7: 46053
A8: LN00277 | B8: CUST0184 | C8: Delhi_North | D8: North | E8: RM_1 | F8: OD | G8: 13140523 | H8: 8984962 | I8: 4155561 | J8: 0.68 | K8: 9.53 | L8: 30 | M8: SMA-0 | N8: 0 | O8: Low | P8: 0 | Q8: 5 | R8: Others | S8: Pharma | T8: 20 | U8: 277070065 | V8: C | W8: 44532 | X8: 44541 | Y8: 46053
A9: LN00276 | B9: CUST0047 | C9: Bangalore_South | D9: East | E9: RM_2 | F9: LAP | G9: 6622064 | H9: 5452052 | I9: 1170012 | J9: 0.82 | K9: 11.82 | L9: 16 | M9: SMA-0 | N9: 0 | O9: Low | P9: 1 | Q9: 5 | R9: Others | S9: FMCG | T9: 2 | U9: 188745315 | V9: A | W9: 43996 | X9: 44000 | Y9: 46053
A10: LN00275 | B10: CUST0018 | C10: Bangalore_South | D10: West | E10: RM_4 | F10: OD | G10: 4337169 | H10: 3528936 | I10: 808233 | J10: 0.81 | K10: 14.42 | L10: 28 | M10: SMA-0 | N10: 0 | O10: Low | P10: 0 | Q10: 1 | R10: Others | S10: Electronics | T10: 14 | U10: 314915960 | V10: A | W10: 44499 | X10: 44504 | Y10: 46053
A11: LN00274 | B11: CUST0024 | C11: Delhi_North | D11: North | E11: RM_10 | F11: CC | G11: 10110939 | H11: 8628597 | I11: 1482342 | J11: 0.85 | K11: 11.77 | L11: 2 | M11: SMA-0 | N11: 0 | O11: Low | P11: 0 | Q11: 5 | R11: Others | S11: Electronics | T11: 12 | U11: 469936343 | V11: B | W11: 44024 | X11: 44026 | Y11: 46053
A12: LN00263 | B12: CUST0112 | C12: Mumbai_Central | D12: East | E12: RM_7 | F12: Term Loan | G12: 2364729 | H12: 1925727 | I12: 439002 | J12: 0.81 | K12: 12.43 | L12: 10 | M12: SMA-0 | N12: 0 | O12: Low | P12: 1 | Q12: 4 | R12: Others | S12: Electronics | T12: 9 | U12: 7123436 | V12: A | W12: 43931 | X12: 43938 | Y12: 46053
A13: LN00260 | B13: CUST0149 | C13: Delhi_North | D13: West | E13: RM_1 | F13: LAP | G13: 8586046 | H13: 7727418 | I13: 858628 | J13: 0.9 | K13: 10.96 | L13: 15 | M13: SMA-0 | N13: 0 | O13: Low | P13: 0 | Q13: 3 | R13: Others | S13: FMCG | T13: 13 | U13: 389324304 | V13: D | W13: 44333 | X13: 44337 | Y13: 46053
... A74: LN00077 | B74: CUST0029 | C74: Kolkata_East | D74: North | E74: RM_1 | F74: OD | G74: 13085553 | H74: 10499966 | I74: 2585587 | J74: 0.8 | K74: 13.7 | L74: 37 | M74: SMA-1 | N74: 0 | O74: Medium | P74: 0 | Q74: 3 | R74: Others | S74: Electronics | T74: 4 | U74: 199924117 | V74: A | W74: 43954 | X74: 43964 | Y74: 46053

Sheet Dashboard Github
A1: KPI | B1: Value
A2: Total Exposure | B2: =KPI!B1 -> 2062659900
A3: Total Accounts | B3: =KPI!B6 -> 300
A4: Gross NPA% | B4: =KPI!B2 -> 0.030279296
A5: High Risk % | B5: =KPI!B3 -> 0.06635974
A8: Branch Wise Exposure Distribution
A10: Branch | B10: Exposure | C10: NPA%
A11: Bangalore_South | B11: =SUMIFS(Table1[Outstanding_Amount],Table1[Branch],A11) -> 371162795 | C11: =SUMIFS(Table1[Outstanding_Amount],Table1[Branch],A11,Table1[NPA_Flag],1)/SUMIFS(Table1[Outstanding_Amount],Table1[Branch],A11)*100 -> 0
A12: Kolkata_East | B12: =SUMIFS(Table1[Outstanding_Amount],Table1[Branch],A12) -> 535687904 | C12: =SUMIFS(Table1[Outstanding_Amount],Table1[Branch],A12,Table1[NPA_Flag],1)/SUMIFS(Table1[Outstanding_Amount],Table1[Branch],A12)*100 -> 8.7514883
A13: Mumbai_Central | B13: =SUMIFS(Table1[Outstanding_Amount],Table1[Branch],A13) -> 569128135 | C13: =SUMIFS(Table1[Outstanding_Amount],Table1[Branch],A13,Table1[NPA_Flag],1)/SUMIFS(Table1[Outstanding_Amount],Table1[Branch],A13)*100 -> 2.7366818
A14: Delhi_North | B14: =SUMIFS(Table1[Outstanding_Amount],Table1[Branch],A14) -> 586681066 | C14: =SUMIFS(Table1[Outstanding_Amount],Table1[Branch],A14,Table1[NPA_Flag],1)/SUMIFS(Table1[Outstanding_Amount],Table1[Branch],A14)*100 -> 0
A26: Branch Wise NPA Ratio
A28: Branch | B28: NPA%
A29: Kolkata_East | B29: =SUMIFS(Table1[Outstanding_Amount],Table1[Branch],A29,Table1[NPA_Flag],1)/SUMIFS(Table1[Outstanding_Amount],Table1[Branch],A29) -> 0.087514883
A30: Mumbai_Central | B30: =SUMIFS(Table1[Outstanding_Amount],Table1[Branch],A30,Table1[NPA_Flag],1)/SUMIFS(Table1[Outstanding_Amount],Table1[Branch],A30) -> 0.027366818
A31: Bangalore_South | B31: =SUMIFS(Table1[Outstanding_Amount],Table1[Branch],A31,Table1[NPA_Flag],1)/SUMIFS(Table1[Outstanding_Amount],Table1[Branch],A31) -> 0
A32: Delhi_North | B32: =SUMIFS(Table1[Outstanding_Amount],Table1[Branch],A32,Table1[NPA_Flag],1)/SUMIFS(Table1[Outstanding_Amount],Table1[Branch],A32) -> 0
A45: Sector Wise Exposure distribution
A47: Sector | B47: Percentage of Total
A48: Others | B48: 0.22550209
A49: Services | B49: 0.23745582
A50: Trading | B50: 0.2635894
A51: Manufacturing | B51: 0.27345269
A52: Grand Total | B52: 1
A60: Risk Category Distribution
A62: Risk Category | B62: percentage of total
A63: High | B63: 0.06635974
A64: Low | B64: 0.85293637
A65: Medium | B65: 0.08070389
A66: Grand Total | B66: 1
C103: Top 10 Exposure Table
A105: Rank | B105: Customer ID | C105: Branch | D105: Sector | E105: Outstanding
A106: 1 | B106: =INDEX(Table1[Customer_ID], MATCH(E106, Table1[Outstanding_Amount], 0)) -> CUST0005 | C106: =INDEX(Table1[Branch], MATCH(E106, Table1[Outstanding_Amount], 0)) -> Mumbai_Central | D106: =INDEX(Table1[Sector], MATCH(E106, Table1[Outstanding_Amount], 0)) -> Services | E106: =LARGE(Table1[Outstanding_Amount],1) -> 13622740
A107: 2 | B107: =INDEX(Table1[Customer_ID], MATCH(E107, Table1[Outstanding_Amount], 0)) -> CUST0182 | C107: =INDEX(Table1[Branch], MATCH(E107, Table1[Outstanding_Amount], 0)) -> Kolkata_East | D107: =INDEX(Table1[Sector], MATCH(E107, Table1[Outstanding_Amount], 0)) -> Manufacturing | E107: =LARGE(Table1[Outstanding_Amount],2) -> 13458128 | J107: Total Exposure | K107: =SUM(Table1[Outstanding_Amount]) -> 2062659900
A108: 3 | B108: =INDEX(Table1[Customer_ID], MATCH(E108, Table1[Outstanding_Amount], 0)) -> CUST0051 | C108: =INDEX(Table1[Branch], MATCH(E108, Table1[Outstanding_Amount], 0)) -> Mumbai_Central | D108: =INDEX(Table1[Sector], MATCH(E108, Table1[Outstanding_Amount], 0)) -> Services | E108: =LARGE(Table1[Outstanding_Amount],3) -> 12775969
A109: 4 | B109: =INDEX(Table1[Customer_ID], MATCH(E109, Table1[Outstanding_Amount], 0)) -> CUST0175 | C109: =INDEX(Table1[Branch], MATCH(E109, Table1[Outstanding_Amount], 0)) -> Kolkata_East | D109: =INDEX(Table1[Sector], MATCH(E109, Table1[Outstanding_Amount], 0)) -> Services | E109: =LARGE(Table1[Outstanding_Amount],4) -> 12758386
A110: 5 | B110: =INDEX(Table1[Customer_ID], MATCH(E110, Table1[Outstanding_Amount], 0)) -> CUST0086 | C110: =INDEX(Table1[Branch], MATCH(E110, Table1[Outstanding_Amount], 0)) -> Kolkata_East | D110: =INDEX(Table1[Sector], MATCH(E110, Table1[Outstanding_Amount], 0)) -> Services | E110: =LARGE(Table1[Outstanding_Amount],5) -> 12710230
A111: 6 | B111: =INDEX(Table1[Customer_ID], MATCH(E111, Table1[Outstanding_Amount], 0)) -> CUST0048 | C111: =INDEX(Table1[Branch], MATCH(E111, Table1[Outstanding_Amount], 0)) -> Delhi_North | D111: =INDEX(Table1[Sector], MATCH(E111, Table1[Outstanding_Amount], 0)) -> Trading | E111: =LARGE(Table1[Outstanding_Amount],6) -> 12656250
A112: 7 | B112: =INDEX(Table1[Customer_ID], MATCH(E112, Table1[Outstanding_Amount], 0)) -> CUST0192 | C112: =INDEX(Table1[Branch], MATCH(E112, Table1[Outstanding_Amount], 0)) -> Bangalore_South | D112: =INDEX(Table1[Sector], MATCH(E112, Table1[Outstanding_Amount], 0)) -> Manufacturing | E112: =LARGE(Table1[Outstanding_Amount],7) -> 12511334 | I112: Top 10 Exposure Percentage | K112: =SUM(Table9[Outstanding])/K107 -> 0.061753009
A113: 8 | B113: =INDEX(Table1[Customer_ID], MATCH(E113, Table1[Outstanding_Amount], 0)) -> CUST0138 | C113: =INDEX(Table1[Branch], MATCH(E113, Table1[Outstanding_Amount], 0)) -> Kolkata_East | D113: =INDEX(Table1[Sector], MATCH(E113, Table1[Outstanding_Amount], 0)) -> Manufacturing | E113: =LARGE(Table1[Outstanding_Amount],8) -> 12331650 | I113: Top 5 Exposure Percentage | K113: =SUM(E106:E110)/K107 -> 0.031670492
...

Sheet Dashboard 1
A1: KPI | B1: Value
A2: Total Exposure | B2: =KPI!B1 -> 2062659900
A3: Total Accounts | B3: =KPI!B6 -> 300
A4: Gross NPA% | B4: =KPI!B2 -> 0.030279296
A5: High Risk % | B5: =KPI!B3 -> 0.06635974
A8: Branch | B8: Exposure | C8: NPA%
A9: Bangalore_South | B9: =SUMIFS(Table1[Outstanding_Amount],Table1[Branch],A9) -> 371162795 | C9: =SUMIFS(Table1[Outstanding_Amount],Table1[Branch],A9,Table1[NPA_Flag],1)/SUMIFS(Table1[Outstanding_Amount],Table1[Branch],A9)*100 -> 0
A10: Kolkata_East | B10: =SUMIFS(Table1[Outstanding_Amount],Table1[Branch],A10) -> 535687904 | C10: =SUMIFS(Table1[Outstanding_Amount],Table1[Branch],A10,Table1[NPA_Flag],1)/SUMIFS(Table1[Outstanding_Amount],Table1[Branch],A10)*100 -> 8.7514883
A11: Mumbai_Central | B11: =SUMIFS(Table1[Outstanding_Amount],Table1[Branch],A11) -> 569128135 | C11: =SUMIFS(Table1[Outstanding_Amount],Table1[Branch],A11,Table1[NPA_Flag],1)/SUMIFS(Table1[Outstanding_Amount],Table1[Branch],A11)*100 -> 2.7366818
A12: Delhi_North | B12: =SUMIFS(Table1[Outstanding_Amount],Table1[Branch],A12) -> 586681066 | C12: =SUMIFS(Table1[Outstanding_Amount],Table1[Branch],A12,Table1[NPA_Flag],1)/SUMIFS(Table1[Outstanding_Amount],Table1[Branch],A12)*100 -> 0
A28: Branch | B28: NPA%
A29: Kolkata_East | B29: =SUMIFS(Table1[Outstanding_Amount],Table1[Branch],A29,Table1[NPA_Flag],1)/SUMIFS(Table1[Outstanding_Amount],Table1[Branch],A29) -> 0.087514883
A30: Mumbai_Central | B30: =SUMIFS(Table1[Outstanding_Amount],Table1[Branch],A30,Table1[NPA_Flag],1)/SUMIFS(Table1[Outstanding_Amount],Table1[Branch],A30) -> 0.027366818
A31: Bangalore_South | B31: =SUMIFS(Table1[Outstanding_Amount],Table1[Branch],A31,Table1[NPA_Flag],1)/SUMIFS(Table1[Outstanding_Amount],Table1[Branch],A31) -> 0
A32: Delhi_North | B32: =SUMIFS(Table1[Outstanding_Amount],Table1[Branch],A32,Table1[NPA_Flag],1)/SUMIFS(Table1[Outstanding_Amount],Table1[Branch],A32) -> 0
A47: Sector | B47: Percentage of Total
A48: Others | B48: 0.22550209
A49: Services | B49: 0.23745582
A50: Trading | B50: 0.2635894
A51: Manufacturing | B51: 0.27345269
A52: Grand Total | B52: 1
A62: Risk Category | B62: percentage of total
A63: High | B63: 0.06635974
A64: Low | B64: 0.85293637
A65: Medium | B65: 0.08070389
A66: Grand Total | B66: 1

Sheet Top Exposure Helper
A1: Customer ID | B1: Branch | C1: Sector | D1: Outstanding
A2: =INDEX(Table1[Customer_ID], MATCH(D2, Table1[Outstanding_Amount], 0)) -> CUST0005 | B2: =INDEX(Table1[Branch], MATCH(D2, Table1[Outstanding_Amount], 0)) -> Mumbai_Central | C2: =INDEX(Table1[Sector], MATCH(D2, Table1[Outstanding_Amount], 0)) -> Services | D2: =LARGE(Table1[Outstanding_Amount],1) -> 13622740
A3: =INDEX(Table1[Customer_ID], MATCH(D3, Table1[Outstanding_Amount], 0)) -> CUST0182 | B3: =INDEX(Table1[Branch], MATCH(D3, Table1[Outstanding_Amount], 0)) -> Kolkata_East | C3: =INDEX(Table1[Sector], MATCH(D3, Table1[Outstanding_Amount], 0)) -> Manufacturing | D3: =LARGE(Table1[Outstanding_Amount],2) -> 13458128
A4: =INDEX(Table1[Customer_ID], MATCH(D4, Table1[Outstanding_Amount], 0)) -> CUST0051 | B4: =INDEX(Table1[Branch], MATCH(D4, Table1[Outstanding_Amount], 0)) -> Mumbai_Central | C4: =INDEX(Table1[Sector], MATCH(D4, Table1[Outstanding_Amount], 0)) -> Services | D4: =LARGE(Table1[Outstanding_Amount],3) -> 12775969
A5: =INDEX(Table1[Customer_ID], MATCH(D5, Table1[Outstanding_Amount], 0)) -> CUST0175 | B5: =INDEX(Table1[Branch], MATCH(D5, Table1[Outstanding_Amount], 0)) -> Kolkata_East | C5: =INDEX(Table1[Sector], MATCH(D5, Table1[Outstanding_Amount], 0)) -> Services | D5: =LARGE(Table1[Outstanding_Amount],4) -> 12758386
A6: =INDEX(Table1[Customer_ID], MATCH(D6, Table1[Outstanding_Amount], 0)) -> CUST0086 | B6: =INDEX(Table1[Branch], MATCH(D6, Table1[Outstanding_Amount], 0)) -> Kolkata_East | C6: =INDEX(Table1[Sector], MATCH(D6, Table1[Outstanding_Amount], 0)) -> Services | D6: =LARGE(Table1[Outstanding_Amount],5) -> 12710230
A7: =INDEX(Table1[Customer_ID], MATCH(D7, Table1[Outstanding_Amount], 0)) -> CUST0048 | B7: =INDEX(Table1[Branch], MATCH(D7, Table1[Outstanding_Amount], 0)) -> Delhi_North | C7: =INDEX(Table1[Sector], MATCH(D7, Table1[Outstanding_Amount], 0)) -> Trading | D7: =LARGE(Table1[Outstanding_Amount],6) -> 12656250
A8: =INDEX(Table1[Customer_ID], MATCH(D8, Table1[Outstanding_Amount], 0)) -> CUST0192 | B8: =INDEX(Table1[Branch], MATCH(D8, Table1[Outstanding_Amount], 0)) -> Bangalore_South | C8: =INDEX(Table1[Sector], MATCH(D8, Table1[Outstanding_Amount], 0)) -> Manufacturing | D8: =LARGE(Table1[Outstanding_Amount],7) -> 12511334
A9: =INDEX(Table1[Customer_ID], MATCH(D9, Table1[Outstanding_Amount], 0)) -> CUST0138 | B9: =INDEX(Table1[Branch], MATCH(D9, Table1[Outstanding_Amount], 0)) -> Kolkata_East | C9: =INDEX(Table1[Sector], MATCH(D9, Table1[Outstanding_Amount], 0)) -> Manufacturing | D9: =LARGE(Table1[Outstanding_Amount],8) -> 12331650
A10: =INDEX(Table1[Customer_ID], MATCH(D10, Table1[Outstanding_Amount], 0)) -> CUST0130 | B10: =INDEX(Table1[Branch], MATCH(D10, Table1[Outstanding_Amount], 0)) -> Bangalore_South | C10: =INDEX(Table1[Sector], MATCH(D10, Table1[Outstanding_Amount], 0)) -> Services | D10: =LARGE(Table1[Outstanding_Amount],9) -> 12283540
A11: =INDEX(Table1[Customer_ID], MATCH(D11, Table1[Outstanding_Amount], 0)) -> CUST0150 | B11: =INDEX(Table1[Branch], MATCH(D11, Table1[Outstanding_Amount], 0)) -> Mumbai_Central | C11: =INDEX(Table1[Sector], MATCH(D11, Table1[Outstanding_Amount], 0)) -> Services | D11: =LARGE(Table1[Outstanding_Amount],10) -> 12267228
A15: Customer ID | B15: Branch | C15: Sector | D15: Outstanding
A16: =A2 -> CUST0005 | B16: =B2 -> Mumbai_Central | C16: =C2 -> Services | D16: =D2 -> 13622740
A17: =A3 -> CUST0182 | B17: =B3 -> Kolkata_East | C17: =C3 -> Manufacturing | D17: =D3 -> 13458128
A18: =A4 -> CUST0051 | B18: =B4 -> Mumbai_Central | C18: =C4 -> Services | D18: =D4 -> 12775969
A19: =A5 -> CUST0175 | B19: =B5 -> Kolkata_East | C19: =C5 -> Services | D19: =D5 -> 12758386
A20: =A6 -> CUST0086 | B20: =B6 -> Kolkata_East | C20: =C6 -> Services | D20: =D6 -> 12710230
A21: =A7 -> CUST0048 | B21: =B7 -> Delhi_North | C21: =C7 -> Trading | D21: =D7 -> 12656250
A22: =A8 -> CUST0192 | B22: =B8 -> Bangalore_South | C22: =C8 -> Manufacturing | D22: =D8 -> 12511334
A23: =A9 -> CUST0138 | B23: =B9 -> Kolkata_East | C23: =C9 -> Manufacturing | D23: =D9 -> 12331650
A24: =A10 -> CUST0130 | B24: =B10 -> Bangalore_South | C24: =C10 -> Services | D24: =D10 -> 12283540
A25: =A11 -> CUST0150 | B25: =B11 -> Mumbai_Central | C25: =C11 -> Services | D25: =D11 -> 12267228
